<!DOCTYPE html>
<html lang="zh-CN">
<head>
  <meta charset="UTF-8">
<meta name="viewport" content="width=device-width, initial-scale=1, maximum-scale=2">
<meta name="theme-color" content="#222">
<meta name="generator" content="Hexo 4.2.1">
  <link rel="apple-touch-icon" sizes="180x180" href="/images/apple-touch-icon-next.png">
  <link rel="icon" type="image/png" sizes="32x32" href="/images/favicon-32x32-next.png">
  <link rel="icon" type="image/png" sizes="16x16" href="/images/favicon-16x16-next.png">
  <link rel="mask-icon" href="/images/logo.svg" color="#222">

<link rel="stylesheet" href="/css/main.css">


<link rel="stylesheet" href="/lib/font-awesome/css/all.min.css">

<script id="hexo-configurations">
    var NexT = window.NexT || {};
    var CONFIG = {"hostname":"yoursite.com","root":"/","scheme":"Gemini","version":"7.8.0","exturl":false,"sidebar":{"position":"left","display":"post","padding":18,"offset":12,"onmobile":false},"copycode":{"enable":false,"show_result":false,"style":null},"back2top":{"enable":true,"sidebar":false,"scrollpercent":false},"bookmark":{"enable":false,"color":"#222","save":"auto"},"fancybox":false,"mediumzoom":false,"lazyload":false,"pangu":false,"comments":{"style":"tabs","active":null,"storage":true,"lazyload":false,"nav":null},"algolia":{"hits":{"per_page":10},"labels":{"input_placeholder":"Search for Posts","hits_empty":"We didn't find any results for the search: ${query}","hits_stats":"${hits} results found in ${time} ms"}},"localsearch":{"enable":false,"trigger":"auto","top_n_per_article":1,"unescape":false,"preload":false},"motion":{"enable":true,"async":false,"transition":{"post_block":"fadeIn","post_header":"slideDownIn","post_body":"slideDownIn","coll_header":"slideLeftIn","sidebar":"slideUpIn"}}};
  </script>

  <meta name="description" content="为了方便的处理程序运行的过程中可能发生的错误，高级语言通常都内置了一套try…except…finally…的错误处理机制，Python也不例外。 当我们认为某些代码可能会出错时，就可以用try来运行这段代码，如果执行出错，则后续代码不会继续执行，而是直接跳转至错误处理代码，即except语句块，执行完except后，如果有finally语句块，则执行finally语句块。 例如： 1234567">
<meta property="og:type" content="article">
<meta property="og:title" content="错误处理">
<meta property="og:url" content="http://yoursite.com/2020/09/11/%E9%94%99%E8%AF%AF%E5%A4%84%E7%90%86/index.html">
<meta property="og:site_name" content="Will&#39;s Blog">
<meta property="og:description" content="为了方便的处理程序运行的过程中可能发生的错误，高级语言通常都内置了一套try…except…finally…的错误处理机制，Python也不例外。 当我们认为某些代码可能会出错时，就可以用try来运行这段代码，如果执行出错，则后续代码不会继续执行，而是直接跳转至错误处理代码，即except语句块，执行完except后，如果有finally语句块，则执行finally语句块。 例如： 1234567">
<meta property="og:locale" content="zh_CN">
<meta property="article:published_time" content="2020-09-11T02:19:47.000Z">
<meta property="article:modified_time" content="2021-01-19T11:54:09.434Z">
<meta property="article:author" content="Will Wan">
<meta name="twitter:card" content="summary">

<link rel="canonical" href="http://yoursite.com/2020/09/11/%E9%94%99%E8%AF%AF%E5%A4%84%E7%90%86/">


<script id="page-configurations">
  // https://hexo.io/docs/variables.html
  CONFIG.page = {
    sidebar: "",
    isHome : false,
    isPost : true,
    lang   : 'zh-CN'
  };
</script>

  <title>错误处理 | Will's Blog</title>
  






  <noscript>
  <style>
  .use-motion .brand,
  .use-motion .menu-item,
  .sidebar-inner,
  .use-motion .post-block,
  .use-motion .pagination,
  .use-motion .comments,
  .use-motion .post-header,
  .use-motion .post-body,
  .use-motion .collection-header { opacity: initial; }

  .use-motion .site-title,
  .use-motion .site-subtitle {
    opacity: initial;
    top: initial;
  }

  .use-motion .logo-line-before i { left: initial; }
  .use-motion .logo-line-after i { right: initial; }
  </style>
</noscript>

</head>

<body itemscope itemtype="http://schema.org/WebPage">
  <div class="container use-motion">
    <div class="headband"></div>

    <header class="header" itemscope itemtype="http://schema.org/WPHeader">
      <div class="header-inner"><div class="site-brand-container">
  <div class="site-nav-toggle">
    <div class="toggle" aria-label="切换导航栏">
      <span class="toggle-line toggle-line-first"></span>
      <span class="toggle-line toggle-line-middle"></span>
      <span class="toggle-line toggle-line-last"></span>
    </div>
  </div>

  <div class="site-meta">

    <a href="/" class="brand" rel="start">
      <span class="logo-line-before"><i></i></span>
      <h1 class="site-title">Will's Blog</h1>
      <span class="logo-line-after"><i></i></span>
    </a>
      <p class="site-subtitle" itemprop="description">Where there is a will, there is a way</p>
  </div>

  <div class="site-nav-right">
    <div class="toggle popup-trigger">
    </div>
  </div>
</div>




<nav class="site-nav">
  <ul id="menu" class="main-menu menu">
        <li class="menu-item menu-item-home">

    <a href="/" rel="section"><i class="fa fa-home fa-fw"></i>首页</a>

  </li>
        <li class="menu-item menu-item-tags">

    <a href="/tags/" rel="section"><i class="fa fa-tags fa-fw"></i>标签</a>

  </li>
        <li class="menu-item menu-item-categories">

    <a href="/categories/" rel="section"><i class="fa fa-th fa-fw"></i>分类</a>

  </li>
        <li class="menu-item menu-item-archives">

    <a href="/archives/" rel="section"><i class="fa fa-archive fa-fw"></i>归档</a>

  </li>
  </ul>
</nav>




</div>
    </header>

    
  <div class="back-to-top">
    <i class="fa fa-arrow-up"></i>
    <span>0%</span>
  </div>


    <main class="main">
      <div class="main-inner">
        <div class="content-wrap">
          

          <div class="content post posts-expand">
            

    
  
  
  <article itemscope itemtype="http://schema.org/Article" class="post-block" lang="zh-CN">
    <link itemprop="mainEntityOfPage" href="http://yoursite.com/2020/09/11/%E9%94%99%E8%AF%AF%E5%A4%84%E7%90%86/">

    <span hidden itemprop="author" itemscope itemtype="http://schema.org/Person">
      <meta itemprop="image" content="/images/avatar.jpg">
      <meta itemprop="name" content="Will Wan">
      <meta itemprop="description" content="">
    </span>

    <span hidden itemprop="publisher" itemscope itemtype="http://schema.org/Organization">
      <meta itemprop="name" content="Will's Blog">
    </span>
      <header class="post-header">
        <h1 class="post-title" itemprop="name headline">
          错误处理
        </h1>

        <div class="post-meta">
            <span class="post-meta-item">
              <span class="post-meta-item-icon">
                <i class="far fa-calendar"></i>
              </span>
              <span class="post-meta-item-text">发表于</span>

              <time title="创建时间：2020-09-11 10:19:47" itemprop="dateCreated datePublished" datetime="2020-09-11T10:19:47+08:00">2020-09-11</time>
            </span>
              <span class="post-meta-item">
                <span class="post-meta-item-icon">
                  <i class="far fa-calendar-check"></i>
                </span>
                <span class="post-meta-item-text">更新于</span>
                <time title="修改时间：2021-01-19 19:54:09" itemprop="dateModified" datetime="2021-01-19T19:54:09+08:00">2021-01-19</time>
              </span>
            <span class="post-meta-item">
              <span class="post-meta-item-icon">
                <i class="far fa-folder"></i>
              </span>
              <span class="post-meta-item-text">分类于</span>
                <span itemprop="about" itemscope itemtype="http://schema.org/Thing">
                  <a href="/categories/python/" itemprop="url" rel="index"><span itemprop="name">python</span></a>
                </span>
            </span>

          

        </div>
      </header>

    
    
    
    <div class="post-body" itemprop="articleBody">

      
        <p>为了方便的处理程序运行的过程中可能发生的错误，高级语言通常都内置了一套try…except…finally…的错误处理机制，Python也不例外。</p>
<p><strong>当我们认为某些代码可能会出错时，就可以用try来运行这段代码</strong>，如果执行出错，则后续代码不会继续执行，而是直接跳转至错误处理代码，即except语句块，执行完except后，如果有finally语句块，则执行finally语句块。</p>
<p>例如：</p>
<figure class="highlight py"><table><tr><td class="gutter"><pre><span class="line">1</span><br><span class="line">2</span><br><span class="line">3</span><br><span class="line">4</span><br><span class="line">5</span><br><span class="line">6</span><br><span class="line">7</span><br><span class="line">8</span><br><span class="line">9</span><br></pre></td><td class="code"><pre><span class="line"><span class="keyword">try</span>:</span><br><span class="line">    print(<span class="string">'try...'</span>)</span><br><span class="line">    r = <span class="number">10</span> / <span class="number">0</span></span><br><span class="line">    print(<span class="string">'result:'</span>, r)</span><br><span class="line"><span class="keyword">except</span> ZeroDivisionError <span class="keyword">as</span> e:</span><br><span class="line">    print(<span class="string">'except:'</span>, e)</span><br><span class="line"><span class="keyword">finally</span>:</span><br><span class="line">    print(<span class="string">'finally...'</span>)</span><br><span class="line">    print(<span class="string">'END'</span>)</span><br></pre></td></tr></table></figure>

<p>上面的代码在计算10 / 0时会产生一个除法运算错误：</p>
<figure class="highlight py"><table><tr><td class="gutter"><pre><span class="line">1</span><br><span class="line">2</span><br><span class="line">3</span><br><span class="line">4</span><br></pre></td><td class="code"><pre><span class="line"><span class="keyword">try</span>...</span><br><span class="line"><span class="keyword">except</span>: division by zero</span><br><span class="line"><span class="keyword">finally</span>...</span><br><span class="line">END</span><br></pre></td></tr></table></figure>

<p>从输出可以看到，当错误发生时，后续语句print(‘result:’, r)不会被执行，except由于捕获到ZeroDivisionError，因此被执行。最后，finally语句被执行。</p>
<p>错误应该有很多种类，如果发生了不同类型的错误，应该由不同的except语句块处理。没错，可以有多个except来捕获不同类型的错误：</p>
<figure class="highlight py"><table><tr><td class="gutter"><pre><span class="line">1</span><br><span class="line">2</span><br><span class="line">3</span><br><span class="line">4</span><br><span class="line">5</span><br><span class="line">6</span><br><span class="line">7</span><br><span class="line">8</span><br><span class="line">9</span><br><span class="line">10</span><br><span class="line">11</span><br><span class="line">12</span><br><span class="line">13</span><br></pre></td><td class="code"><pre><span class="line"><span class="keyword">try</span>:</span><br><span class="line">    print(<span class="string">'try...'</span>)</span><br><span class="line">    r = <span class="number">10</span> / int(<span class="string">'2'</span>)</span><br><span class="line">    print(<span class="string">'result:'</span>, r)</span><br><span class="line"><span class="keyword">except</span> ValueError <span class="keyword">as</span> e:</span><br><span class="line">    print(<span class="string">'ValueError:'</span>, e)</span><br><span class="line"><span class="keyword">except</span> ZeroDivisionError <span class="keyword">as</span> e:</span><br><span class="line">    print(<span class="string">'ZeroDivisionError:'</span>, e)</span><br><span class="line"><span class="keyword">else</span>:</span><br><span class="line">    print(<span class="string">'no error!'</span>)</span><br><span class="line"><span class="keyword">finally</span>:</span><br><span class="line">    print(<span class="string">'finally...'</span>)</span><br><span class="line">print(<span class="string">'END'</span>)</span><br></pre></td></tr></table></figure>

<p>int()函数可能会抛出ValueError，所以我们用一个except捕获ValueError，用另一个except捕获ZeroDivisionError。</p>
<p>此外，如果没有错误发生，可以在except语句块后面加一个else，当没有错误发生时，会自动执行else语句。</p>
<p>ython的错误其实也是class，所有的错误类型都继承自BaseException，所以在使用except时需要注意的是，它不但捕获该类型的错误，还把其子类也“一网打尽”。比如：</p>
<figure class="highlight py"><table><tr><td class="gutter"><pre><span class="line">1</span><br><span class="line">2</span><br><span class="line">3</span><br><span class="line">4</span><br><span class="line">5</span><br><span class="line">6</span><br></pre></td><td class="code"><pre><span class="line"><span class="keyword">try</span>:</span><br><span class="line">    foo()</span><br><span class="line"><span class="keyword">except</span> ValueError <span class="keyword">as</span> e:</span><br><span class="line">    print(<span class="string">'ValueError'</span>)</span><br><span class="line"><span class="keyword">except</span> UnicodeError <span class="keyword">as</span> e:</span><br><span class="line">    print(<span class="string">'UnicodeError'</span>)</span><br></pre></td></tr></table></figure>

<p>第二个except永远也捕获不到UnicodeError，因为UnicodeError是ValueError的子类，如果有，也被第一个except给捕获了。</p>
<p>Python所有的错误都是从BaseException类派生的，常见的错误类型和继承关系看<a href="https://docs.python.org/3/library/exceptions.html#exception-hierarchy" target="_blank" rel="noopener">这里</a>。</p>
<p><strong>使用try…except捕获错误还有一个巨大的好处，就是可以跨越多层调用</strong>，比如函数main()调用bar()，bar()调用foo()，结果foo()出错了，这时，只要main()捕获到了，就可以处理：</p>
<figure class="highlight py"><table><tr><td class="gutter"><pre><span class="line">1</span><br><span class="line">2</span><br><span class="line">3</span><br><span class="line">4</span><br><span class="line">5</span><br><span class="line">6</span><br><span class="line">7</span><br><span class="line">8</span><br><span class="line">9</span><br><span class="line">10</span><br><span class="line">11</span><br><span class="line">12</span><br><span class="line">13</span><br></pre></td><td class="code"><pre><span class="line"><span class="function"><span class="keyword">def</span> <span class="title">foo</span><span class="params">(s)</span>:</span></span><br><span class="line">    <span class="keyword">return</span> <span class="number">10</span> / int(s)</span><br><span class="line"></span><br><span class="line"><span class="function"><span class="keyword">def</span> <span class="title">bar</span><span class="params">(s)</span>:</span></span><br><span class="line">    <span class="keyword">return</span> foo(s) * <span class="number">2</span></span><br><span class="line"></span><br><span class="line"><span class="function"><span class="keyword">def</span> <span class="title">main</span><span class="params">()</span>:</span></span><br><span class="line">    <span class="keyword">try</span>:</span><br><span class="line">        bar(<span class="string">'0'</span>)</span><br><span class="line">    <span class="keyword">except</span> Exception <span class="keyword">as</span> e:</span><br><span class="line">        print(<span class="string">'Error:'</span>, e)</span><br><span class="line">    <span class="keyword">finally</span>:</span><br><span class="line">        print(<span class="string">'finally...'</span>)</span><br></pre></td></tr></table></figure>

<h2 id="调用栈"><a href="#调用栈" class="headerlink" title="调用栈"></a>调用栈</h2><p>如果错误没有被捕获，它就会一直往上抛，最后被Python解释器捕获，打印一个错误信息，然后程序退出。来看看err.py：</p>
<figure class="highlight py"><table><tr><td class="gutter"><pre><span class="line">1</span><br><span class="line">2</span><br><span class="line">3</span><br><span class="line">4</span><br><span class="line">5</span><br><span class="line">6</span><br><span class="line">7</span><br><span class="line">8</span><br><span class="line">9</span><br><span class="line">10</span><br><span class="line">11</span><br></pre></td><td class="code"><pre><span class="line"><span class="comment"># err.py:</span></span><br><span class="line"><span class="function"><span class="keyword">def</span> <span class="title">foo</span><span class="params">(s)</span>:</span></span><br><span class="line">    <span class="keyword">return</span> <span class="number">10</span> / int(s)</span><br><span class="line"></span><br><span class="line"><span class="function"><span class="keyword">def</span> <span class="title">bar</span><span class="params">(s)</span>:</span></span><br><span class="line">    <span class="keyword">return</span> foo(s) * <span class="number">2</span></span><br><span class="line"></span><br><span class="line"><span class="function"><span class="keyword">def</span> <span class="title">main</span><span class="params">()</span>:</span></span><br><span class="line">    bar(<span class="string">'0'</span>)</span><br><span class="line"></span><br><span class="line">main()</span><br></pre></td></tr></table></figure>

<p>执行，结果如下：</p>
<figure class="highlight py"><table><tr><td class="gutter"><pre><span class="line">1</span><br><span class="line">2</span><br><span class="line">3</span><br><span class="line">4</span><br><span class="line">5</span><br><span class="line">6</span><br><span class="line">7</span><br><span class="line">8</span><br><span class="line">9</span><br><span class="line">10</span><br><span class="line">11</span><br></pre></td><td class="code"><pre><span class="line">$ python3 err.py</span><br><span class="line">Traceback (most recent call last):</span><br><span class="line">  File <span class="string">"err.py"</span>, line <span class="number">11</span>, <span class="keyword">in</span> &lt;module&gt;</span><br><span class="line">    main()</span><br><span class="line">  File <span class="string">"err.py"</span>, line <span class="number">9</span>, <span class="keyword">in</span> main</span><br><span class="line">    bar(<span class="string">'0'</span>)</span><br><span class="line">  File <span class="string">"err.py"</span>, line <span class="number">6</span>, <span class="keyword">in</span> bar</span><br><span class="line">    <span class="keyword">return</span> foo(s) * <span class="number">2</span></span><br><span class="line">  File <span class="string">"err.py"</span>, line <span class="number">3</span>, <span class="keyword">in</span> foo</span><br><span class="line">    <span class="keyword">return</span> <span class="number">10</span> / int(s)</span><br><span class="line">ZeroDivisionError: division by zero</span><br></pre></td></tr></table></figure>

<p>出错并不可怕，可怕的是不知道哪里出错了。解读错误信息是定位错误的关键。我们从上往下可以看到整个错误的调用函数链。</p>
<p>错误信息第1行：</p>
<figure class="highlight py"><table><tr><td class="gutter"><pre><span class="line">1</span><br></pre></td><td class="code"><pre><span class="line">Traceback (most recent call last):</span><br></pre></td></tr></table></figure>

<p>告诉我们这是错误的跟踪信息。</p>
<p>第2~3行：</p>
<figure class="highlight py"><table><tr><td class="gutter"><pre><span class="line">1</span><br><span class="line">2</span><br></pre></td><td class="code"><pre><span class="line">File <span class="string">"err.py"</span>, line <span class="number">11</span>, <span class="keyword">in</span> &lt;module&gt;</span><br><span class="line">  main()</span><br></pre></td></tr></table></figure>

<p>调用main()出错了，在代码文件err.py的第11行代码，但原因是第9行：</p>
<figure class="highlight py"><table><tr><td class="gutter"><pre><span class="line">1</span><br><span class="line">2</span><br></pre></td><td class="code"><pre><span class="line">File <span class="string">"err.py"</span>, line <span class="number">9</span>, <span class="keyword">in</span> main</span><br><span class="line">  bar(<span class="string">'0'</span>)</span><br></pre></td></tr></table></figure>

<p>调用bar(‘0’)出错了，在代码文件err.py的第9行代码，但原因是第6行：</p>
<figure class="highlight py"><table><tr><td class="gutter"><pre><span class="line">1</span><br><span class="line">2</span><br></pre></td><td class="code"><pre><span class="line">File <span class="string">"err.py"</span>, line <span class="number">6</span>, <span class="keyword">in</span> bar</span><br><span class="line">  <span class="keyword">return</span> foo(s) * <span class="number">2</span></span><br></pre></td></tr></table></figure>

<p>原因是return foo(s) * 2这个语句出错了，但这还不是最终原因，继续往下看：</p>
<figure class="highlight py"><table><tr><td class="gutter"><pre><span class="line">1</span><br><span class="line">2</span><br></pre></td><td class="code"><pre><span class="line">File <span class="string">"err.py"</span>, line <span class="number">3</span>, <span class="keyword">in</span> foo</span><br><span class="line">  <span class="keyword">return</span> <span class="number">10</span> / int(s)</span><br></pre></td></tr></table></figure>

<p>原因是return 10 / int(s)这个语句出错了，这是错误产生的源头，因为下面打印了：</p>
<figure class="highlight py"><table><tr><td class="gutter"><pre><span class="line">1</span><br></pre></td><td class="code"><pre><span class="line">ZeroDivisionError: integer division <span class="keyword">or</span> modulo by zero</span><br></pre></td></tr></table></figure>

<p>根据错误类型ZeroDivisionError，我们判断，int(s)本身并没有出错，但是int(s)返回0，在计算10 / 0时出错，至此，找到错误源头。</p>
<p><strong>出错的时候，一定要分析错误的调用栈信息，才能定位错误的位置。</strong></p>
<h2 id="记录错误"><a href="#记录错误" class="headerlink" title="记录错误"></a>记录错误</h2><p>如果不捕获错误，自然可以让Python解释器来打印出错误堆栈，但程序也被结束了。<strong>既然我们能捕获错误，就可以把错误堆栈打印出来，然后分析错误原因，同时，让程序继续执行下去</strong>。</p>
<p>Python内置的logging模块可以非常容易地记录错误信息：</p>
<figure class="highlight py"><table><tr><td class="gutter"><pre><span class="line">1</span><br><span class="line">2</span><br><span class="line">3</span><br><span class="line">4</span><br><span class="line">5</span><br><span class="line">6</span><br><span class="line">7</span><br><span class="line">8</span><br><span class="line">9</span><br><span class="line">10</span><br><span class="line">11</span><br><span class="line">12</span><br><span class="line">13</span><br><span class="line">14</span><br><span class="line">15</span><br><span class="line">16</span><br><span class="line">17</span><br><span class="line">18</span><br></pre></td><td class="code"><pre><span class="line"><span class="comment"># err_logging.py</span></span><br><span class="line"></span><br><span class="line"><span class="keyword">import</span> logging</span><br><span class="line"></span><br><span class="line"><span class="function"><span class="keyword">def</span> <span class="title">foo</span><span class="params">(s)</span>:</span></span><br><span class="line">    <span class="keyword">return</span> <span class="number">10</span> / int(s)</span><br><span class="line"></span><br><span class="line"><span class="function"><span class="keyword">def</span> <span class="title">bar</span><span class="params">(s)</span>:</span></span><br><span class="line">    <span class="keyword">return</span> foo(s) * <span class="number">2</span></span><br><span class="line"></span><br><span class="line"><span class="function"><span class="keyword">def</span> <span class="title">main</span><span class="params">()</span>:</span></span><br><span class="line">    <span class="keyword">try</span>:</span><br><span class="line">        bar(<span class="string">'0'</span>)</span><br><span class="line">    <span class="keyword">except</span> Exception <span class="keyword">as</span> e:</span><br><span class="line">        logging.exception(e)</span><br><span class="line"></span><br><span class="line">main()</span><br><span class="line">print(<span class="string">'END'</span>)</span><br></pre></td></tr></table></figure>

<p>同样是出错，但程序打印完错误信息后会继续执行，并正常退出：</p>
<figure class="highlight py"><table><tr><td class="gutter"><pre><span class="line">1</span><br><span class="line">2</span><br><span class="line">3</span><br><span class="line">4</span><br><span class="line">5</span><br><span class="line">6</span><br><span class="line">7</span><br><span class="line">8</span><br><span class="line">9</span><br><span class="line">10</span><br><span class="line">11</span><br></pre></td><td class="code"><pre><span class="line">$ python3 err_logging.py</span><br><span class="line">ERROR:root:division by zero</span><br><span class="line">Traceback (most recent call last):</span><br><span class="line">  File <span class="string">"err_logging.py"</span>, line <span class="number">13</span>, <span class="keyword">in</span> main</span><br><span class="line">    bar(<span class="string">'0'</span>)</span><br><span class="line">  File <span class="string">"err_logging.py"</span>, line <span class="number">9</span>, <span class="keyword">in</span> bar</span><br><span class="line">    <span class="keyword">return</span> foo(s) * <span class="number">2</span></span><br><span class="line">  File <span class="string">"err_logging.py"</span>, line <span class="number">6</span>, <span class="keyword">in</span> foo</span><br><span class="line">    <span class="keyword">return</span> <span class="number">10</span> / int(s)</span><br><span class="line">ZeroDivisionError: division by zero</span><br><span class="line">END</span><br></pre></td></tr></table></figure>

<p>通过配置，logging还可以把错误记录到日志文件里，方便事后排查。</p>
<h2 id="抛出错误"><a href="#抛出错误" class="headerlink" title="抛出错误"></a>抛出错误</h2><p>因为错误是class，捕获一个错误就是捕获到该class的一个实例。因此，错误并不是凭空产生的，而是有意创建并抛出的。Python的内置函数会抛出很多类型的错误，我们自己编写的函数也可以抛出错误。</p>
<p>如果要抛出错误，首先根据需要，可以定义一个错误的class，选择好继承关系，然后，用raise语句抛出一个错误的实例：</p>
<figure class="highlight py"><table><tr><td class="gutter"><pre><span class="line">1</span><br><span class="line">2</span><br><span class="line">3</span><br><span class="line">4</span><br><span class="line">5</span><br><span class="line">6</span><br><span class="line">7</span><br><span class="line">8</span><br><span class="line">9</span><br><span class="line">10</span><br><span class="line">11</span><br></pre></td><td class="code"><pre><span class="line"><span class="comment"># err_raise.py</span></span><br><span class="line"><span class="class"><span class="keyword">class</span> <span class="title">FooError</span><span class="params">(ValueError)</span>:</span></span><br><span class="line">    <span class="keyword">pass</span></span><br><span class="line"></span><br><span class="line"><span class="function"><span class="keyword">def</span> <span class="title">foo</span><span class="params">(s)</span>:</span></span><br><span class="line">    n = int(s)</span><br><span class="line">    <span class="keyword">if</span> n==<span class="number">0</span>:</span><br><span class="line">        <span class="keyword">raise</span> FooError(<span class="string">'invalid value: %s'</span> % s)</span><br><span class="line">    <span class="keyword">return</span> <span class="number">10</span> / n</span><br><span class="line"></span><br><span class="line">foo(<span class="string">'0'</span>)</span><br></pre></td></tr></table></figure>

<p>执行，可以最后跟踪到我们自己定义的错误：</p>
<figure class="highlight py"><table><tr><td class="gutter"><pre><span class="line">1</span><br><span class="line">2</span><br><span class="line">3</span><br><span class="line">4</span><br><span class="line">5</span><br><span class="line">6</span><br><span class="line">7</span><br></pre></td><td class="code"><pre><span class="line">$ python3 err_raise.py </span><br><span class="line">Traceback (most recent call last):</span><br><span class="line">  File <span class="string">"err_throw.py"</span>, line <span class="number">11</span>, <span class="keyword">in</span> &lt;module&gt;</span><br><span class="line">    foo(<span class="string">'0'</span>)</span><br><span class="line">  File <span class="string">"err_throw.py"</span>, line <span class="number">8</span>, <span class="keyword">in</span> foo</span><br><span class="line">    <span class="keyword">raise</span> FooError(<span class="string">'invalid value: %s'</span> % s)</span><br><span class="line">__main__.FooError: invalid value: <span class="number">0</span></span><br></pre></td></tr></table></figure>

<p>只有在必要的时候才定义我们自己的错误类型。<strong>如果可以选择Python已有的内置的错误类型（比如ValueError，TypeError），尽量使用Python内置的错误类型</strong>。</p>
<h2 id="错误处理方式"><a href="#错误处理方式" class="headerlink" title="错误处理方式"></a>错误处理方式</h2><p>我们来看一种错误处理的方式：</p>
<figure class="highlight py"><table><tr><td class="gutter"><pre><span class="line">1</span><br><span class="line">2</span><br><span class="line">3</span><br><span class="line">4</span><br><span class="line">5</span><br><span class="line">6</span><br><span class="line">7</span><br><span class="line">8</span><br><span class="line">9</span><br><span class="line">10</span><br><span class="line">11</span><br><span class="line">12</span><br><span class="line">13</span><br><span class="line">14</span><br><span class="line">15</span><br><span class="line">16</span><br></pre></td><td class="code"><pre><span class="line"><span class="comment"># err_reraise.py</span></span><br><span class="line"></span><br><span class="line"><span class="function"><span class="keyword">def</span> <span class="title">foo</span><span class="params">(s)</span>:</span></span><br><span class="line">    n = int(s)</span><br><span class="line">    <span class="keyword">if</span> n==<span class="number">0</span>:</span><br><span class="line">        <span class="keyword">raise</span> ValueError(<span class="string">'invalid value: %s'</span> % s)</span><br><span class="line">    <span class="keyword">return</span> <span class="number">10</span> / n</span><br><span class="line"></span><br><span class="line"><span class="function"><span class="keyword">def</span> <span class="title">bar</span><span class="params">()</span>:</span></span><br><span class="line">    <span class="keyword">try</span>:</span><br><span class="line">        foo(<span class="string">'0'</span>)</span><br><span class="line">    <span class="keyword">except</span> ValueError <span class="keyword">as</span> e:</span><br><span class="line">        print(<span class="string">'ValueError!'</span>)</span><br><span class="line">        <span class="keyword">raise</span></span><br><span class="line"></span><br><span class="line">bar()</span><br></pre></td></tr></table></figure>

<p>在bar()函数中，我们明明已经捕获了错误，但是，打印一个ValueError!后，又把错误通过raise语句抛出去了。</p>
<p>其实这种错误处理方式相当常见。捕获错误目的只是记录一下，便于后续追踪。但是，由于当前函数不知道应该怎么处理该错误，所以，最恰当的方式是继续往上抛，让顶层调用者去处理。好比一个员工处理不了一个问题时，就把问题抛给他的老板，如果他的老板也处理不了，就一直往上抛，最终会抛给CEO去处理。</p>
<p><strong>raise语句如果不带参数，就会把当前错误原样抛出。此外，在except中raise一个Error，还可以把一种类型的错误转化成另一种类型：</strong></p>
<figure class="highlight py"><table><tr><td class="gutter"><pre><span class="line">1</span><br><span class="line">2</span><br><span class="line">3</span><br><span class="line">4</span><br></pre></td><td class="code"><pre><span class="line"><span class="keyword">try</span>:</span><br><span class="line">    <span class="number">10</span> / <span class="number">0</span></span><br><span class="line"><span class="keyword">except</span> ZeroDivisionError:</span><br><span class="line">    <span class="keyword">raise</span> ValueError(<span class="string">'input error!'</span>)</span><br></pre></td></tr></table></figure>

<p>只要是合理的转换逻辑就可以，但是，决不应该把一个IOError转换成毫不相干的ValueError。</p>
<h2 id="小结"><a href="#小结" class="headerlink" title="小结"></a>小结</h2><p>Python内置的try…except…finally用来处理错误十分方便。出错时，会分析错误信息并定位错误发生的代码位置才是最关键的。</p>
<p>程序也可以主动抛出错误，让调用者来处理相应的错误。但是，应该在文档中写清楚可能会抛出哪些错误，以及错误产生的原因。</p>
<h2 id="参考"><a href="#参考" class="headerlink" title="参考"></a>参考</h2><ul>
<li><a href="https://www.liaoxuefeng.com/wiki/1016959663602400/1017598873256736" target="_blank" rel="noopener">廖雪峰Python教程——错误处理</a></li>
</ul>

    </div>

    
    
    

      <footer class="post-footer">

        


        
    <div class="post-nav">
      <div class="post-nav-item">
    <a href="/2020/09/07/%E9%80%92%E5%BD%92%E5%87%BD%E6%95%B0/" rel="prev" title="递归函数">
      <i class="fa fa-chevron-left"></i> 递归函数
    </a></div>
      <div class="post-nav-item">
    <a href="/2021/01/19/CSS-%E4%B9%8B%E5%90%84%E7%A7%8D%E5%B1%85%E4%B8%AD/" rel="next" title="CSS 之各种居中">
      CSS 之各种居中 <i class="fa fa-chevron-right"></i>
    </a></div>
    </div>
      </footer>
    
  </article>
  
  
  



          </div>
          

<script>
  window.addEventListener('tabs:register', () => {
    let { activeClass } = CONFIG.comments;
    if (CONFIG.comments.storage) {
      activeClass = localStorage.getItem('comments_active') || activeClass;
    }
    if (activeClass) {
      let activeTab = document.querySelector(`a[href="#comment-${activeClass}"]`);
      if (activeTab) {
        activeTab.click();
      }
    }
  });
  if (CONFIG.comments.storage) {
    window.addEventListener('tabs:click', event => {
      if (!event.target.matches('.tabs-comment .tab-content .tab-pane')) return;
      let commentClass = event.target.classList[1];
      localStorage.setItem('comments_active', commentClass);
    });
  }
</script>

        </div>
          
  
  <div class="toggle sidebar-toggle">
    <span class="toggle-line toggle-line-first"></span>
    <span class="toggle-line toggle-line-middle"></span>
    <span class="toggle-line toggle-line-last"></span>
  </div>

  <aside class="sidebar">
    <div class="sidebar-inner">

      <ul class="sidebar-nav motion-element">
        <li class="sidebar-nav-toc">
          文章目录
        </li>
        <li class="sidebar-nav-overview">
          站点概览
        </li>
      </ul>

      <!--noindex-->
      <div class="post-toc-wrap sidebar-panel">
          <div class="post-toc motion-element"><ol class="nav"><li class="nav-item nav-level-2"><a class="nav-link" href="#调用栈"><span class="nav-number">1.</span> <span class="nav-text">调用栈</span></a></li><li class="nav-item nav-level-2"><a class="nav-link" href="#记录错误"><span class="nav-number">2.</span> <span class="nav-text">记录错误</span></a></li><li class="nav-item nav-level-2"><a class="nav-link" href="#抛出错误"><span class="nav-number">3.</span> <span class="nav-text">抛出错误</span></a></li><li class="nav-item nav-level-2"><a class="nav-link" href="#错误处理方式"><span class="nav-number">4.</span> <span class="nav-text">错误处理方式</span></a></li><li class="nav-item nav-level-2"><a class="nav-link" href="#小结"><span class="nav-number">5.</span> <span class="nav-text">小结</span></a></li><li class="nav-item nav-level-2"><a class="nav-link" href="#参考"><span class="nav-number">6.</span> <span class="nav-text">参考</span></a></li></ol></div>
      </div>
      <!--/noindex-->

      <div class="site-overview-wrap sidebar-panel">
        <div class="site-author motion-element" itemprop="author" itemscope itemtype="http://schema.org/Person">
    <img class="site-author-image" itemprop="image" alt="Will Wan"
      src="/images/avatar.jpg">
  <p class="site-author-name" itemprop="name">Will Wan</p>
  <div class="site-description" itemprop="description"></div>
</div>
<div class="site-state-wrap motion-element">
  <nav class="site-state">
      <div class="site-state-item site-state-posts">
          <a href="/archives/">
        
          <span class="site-state-item-count">29</span>
          <span class="site-state-item-name">日志</span>
        </a>
      </div>
      <div class="site-state-item site-state-categories">
            <a href="/categories/">
          
        <span class="site-state-item-count">12</span>
        <span class="site-state-item-name">分类</span></a>
      </div>
      <div class="site-state-item site-state-tags">
            <a href="/tags/">
          
        <span class="site-state-item-count">23</span>
        <span class="site-state-item-name">标签</span></a>
      </div>
  </nav>
</div>



      </div>

    </div>
  </aside>
  <div id="sidebar-dimmer"></div>


      </div>
    </main>

    <footer class="footer">
      <div class="footer-inner">
        

        

<div class="copyright">
  
  &copy; 
  <span itemprop="copyrightYear">2022</span>
  <span class="with-love">
    <i class="fa fa-heart"></i>
  </span>
  <span class="author" itemprop="copyrightHolder">Will Wan</span>
</div>
  <div class="powered-by">由 <a href="https://hexo.io/" class="theme-link" rel="noopener" target="_blank">Hexo</a> & <a href="https://theme-next.org/" class="theme-link" rel="noopener" target="_blank">NexT.Gemini</a> 强力驱动
  </div>

        








      </div>
    </footer>
  </div>

  
  <script src="/lib/anime.min.js"></script>
  <script src="/lib/velocity/velocity.min.js"></script>
  <script src="/lib/velocity/velocity.ui.min.js"></script>

<script src="/js/utils.js"></script>

<script src="/js/motion.js"></script>


<script src="/js/schemes/pisces.js"></script>


<script src="/js/next-boot.js"></script>




  















  

  

</body>
</html>
